2025-01-08 21:00:48,882 INFO    MainThread:39936 [wandb_setup.py:_flush():76] Current SDK version is 0.16.6
2025-01-08 21:00:48,882 INFO    MainThread:39936 [wandb_setup.py:_flush():76] Configure stats pid to 39936
2025-01-08 21:00:48,882 INFO    MainThread:39936 [wandb_setup.py:_flush():76] Loading settings from /home2/kyrylo/.config/wandb/settings
2025-01-08 21:00:48,882 INFO    MainThread:39936 [wandb_setup.py:_flush():76] Loading settings from /home2/kyrylo/Assignments/MLNS-1/wandb/settings
2025-01-08 21:00:48,882 INFO    MainThread:39936 [wandb_setup.py:_flush():76] Loading settings from environment variables: {}
2025-01-08 21:00:48,882 INFO    MainThread:39936 [wandb_setup.py:_flush():76] Inferring run settings from compute environment: {'program_relpath': 'train.py', 'program_abspath': '/home2/kyrylo/Assignments/MLNS-1/train.py', 'program': '/home2/kyrylo/Assignments/MLNS-1/train.py'}
2025-01-08 21:00:48,883 INFO    MainThread:39936 [wandb_setup.py:_flush():76] Applying login settings: {'api_key': '***REDACTED***'}
2025-01-08 21:00:48,883 INFO    MainThread:39936 [wandb_setup.py:_flush():76] Applying login settings: {'api_key': '***REDACTED***'}
2025-01-08 21:00:48,883 INFO    MainThread:39936 [wandb_setup.py:_flush():76] Applying login settings: {}
2025-01-08 21:00:48,883 INFO    MainThread:39936 [wandb_init.py:_log_setup():521] Logging user logs to /home2/kyrylo/Assignments/MLNS-1/wandb/run-20250108_210048-jqfhry9y/logs/debug.log
2025-01-08 21:00:48,883 INFO    MainThread:39936 [wandb_init.py:_log_setup():522] Logging internal logs to /home2/kyrylo/Assignments/MLNS-1/wandb/run-20250108_210048-jqfhry9y/logs/debug-internal.log
2025-01-08 21:00:48,883 INFO    MainThread:39936 [wandb_init.py:init():561] calling init triggers
2025-01-08 21:00:48,883 INFO    MainThread:39936 [wandb_init.py:init():568] wandb.init called with sweep_config: {}
config: {}
2025-01-08 21:00:48,884 INFO    MainThread:39936 [wandb_init.py:init():611] starting backend
2025-01-08 21:00:48,884 INFO    MainThread:39936 [wandb_init.py:init():615] setting up manager
2025-01-08 21:00:48,886 INFO    MainThread:39936 [backend.py:_multiprocessing_setup():105] multiprocessing start_methods=fork,spawn,forkserver, using: spawn
2025-01-08 21:00:48,916 INFO    MainThread:39936 [wandb_init.py:init():623] backend started and connected
2025-01-08 21:00:48,919 INFO    MainThread:39936 [wandb_init.py:init():715] updated telemetry
2025-01-08 21:00:48,920 INFO    MainThread:39936 [wandb_init.py:init():748] communicating run to backend with 90.0 second timeout
2025-01-08 21:01:48,429 INFO    Thread-2 (wrapped_target):39936 [retry.py:__call__():172] Retry attempt failed:
Traceback (most recent call last):
  File "/home2/kyrylo/Minimal/lib/python3.10/site-packages/urllib3/connectionpool.py", line 537, in _make_request
    response = conn.getresponse()
  File "/home2/kyrylo/Minimal/lib/python3.10/site-packages/urllib3/connection.py", line 466, in getresponse
    httplib_response = super().getresponse()
  File "/home2/kyrylo/.pyenv/versions/3.10.12/lib/python3.10/http/client.py", line 1375, in getresponse
    response.begin()
  File "/home2/kyrylo/.pyenv/versions/3.10.12/lib/python3.10/http/client.py", line 318, in begin
    version, status, reason = self._read_status()
  File "/home2/kyrylo/.pyenv/versions/3.10.12/lib/python3.10/http/client.py", line 279, in _read_status
    line = str(self.fp.readline(_MAXLINE + 1), "iso-8859-1")
  File "/home2/kyrylo/.pyenv/versions/3.10.12/lib/python3.10/socket.py", line 705, in readinto
    return self._sock.recv_into(b)
  File "/home2/kyrylo/.pyenv/versions/3.10.12/lib/python3.10/ssl.py", line 1274, in recv_into
    return self.read(nbytes, buffer)
  File "/home2/kyrylo/.pyenv/versions/3.10.12/lib/python3.10/ssl.py", line 1130, in read
    return self._sslobj.read(len, buffer)
TimeoutError: The read operation timed out

The above exception was the direct cause of the following exception:

Traceback (most recent call last):
  File "/home2/kyrylo/Minimal/lib/python3.10/site-packages/requests/adapters.py", line 486, in send
    resp = conn.urlopen(
  File "/home2/kyrylo/Minimal/lib/python3.10/site-packages/urllib3/connectionpool.py", line 847, in urlopen
    retries = retries.increment(
  File "/home2/kyrylo/Minimal/lib/python3.10/site-packages/urllib3/util/retry.py", line 470, in increment
    raise reraise(type(error), error, _stacktrace)
  File "/home2/kyrylo/Minimal/lib/python3.10/site-packages/urllib3/util/util.py", line 39, in reraise
    raise value
  File "/home2/kyrylo/Minimal/lib/python3.10/site-packages/urllib3/connectionpool.py", line 793, in urlopen
    response = self._make_request(
  File "/home2/kyrylo/Minimal/lib/python3.10/site-packages/urllib3/connectionpool.py", line 539, in _make_request
    self._raise_timeout(err=e, url=url, timeout_value=read_timeout)
  File "/home2/kyrylo/Minimal/lib/python3.10/site-packages/urllib3/connectionpool.py", line 370, in _raise_timeout
    raise ReadTimeoutError(
urllib3.exceptions.ReadTimeoutError: HTTPSConnectionPool(host='api.wandb.ai', port=443): Read timed out. (read timeout=20)

During handling of the above exception, another exception occurred:

Traceback (most recent call last):
  File "/home2/kyrylo/Minimal/lib/python3.10/site-packages/wandb/sdk/lib/retry.py", line 131, in __call__
    result = self._call_fn(*args, **kwargs)
  File "/home2/kyrylo/Minimal/lib/python3.10/site-packages/wandb/sdk/internal/internal_api.py", line 369, in execute
    return self.client.execute(*args, **kwargs)  # type: ignore
  File "/home2/kyrylo/Minimal/lib/python3.10/site-packages/wandb/vendor/gql-0.2.0/wandb_gql/client.py", line 52, in execute
    result = self._get_result(document, *args, **kwargs)
  File "/home2/kyrylo/Minimal/lib/python3.10/site-packages/wandb/vendor/gql-0.2.0/wandb_gql/client.py", line 60, in _get_result
    return self.transport.execute(document, *args, **kwargs)
  File "/home2/kyrylo/Minimal/lib/python3.10/site-packages/wandb/sdk/lib/gql_request.py", line 58, in execute
    request = self.session.post(self.url, **post_args)
  File "/home2/kyrylo/Minimal/lib/python3.10/site-packages/requests/sessions.py", line 637, in post
    return self.request("POST", url, data=data, json=json, **kwargs)
  File "/home2/kyrylo/Minimal/lib/python3.10/site-packages/requests/sessions.py", line 589, in request
    resp = self.send(prep, **send_kwargs)
  File "/home2/kyrylo/Minimal/lib/python3.10/site-packages/requests/sessions.py", line 703, in send
    r = adapter.send(request, **kwargs)
  File "/home2/kyrylo/Minimal/lib/python3.10/site-packages/requests/adapters.py", line 532, in send
    raise ReadTimeout(e, request=request)
requests.exceptions.ReadTimeout: HTTPSConnectionPool(host='api.wandb.ai', port=443): Read timed out. (read timeout=20)
2025-01-08 21:02:01,914 INFO    Thread-1 (wrapped_target):39936 [retry.py:__call__():172] Retry attempt failed:
Traceback (most recent call last):
  File "/home2/kyrylo/Minimal/lib/python3.10/site-packages/urllib3/connectionpool.py", line 537, in _make_request
    response = conn.getresponse()
  File "/home2/kyrylo/Minimal/lib/python3.10/site-packages/urllib3/connection.py", line 466, in getresponse
    httplib_response = super().getresponse()
  File "/home2/kyrylo/.pyenv/versions/3.10.12/lib/python3.10/http/client.py", line 1375, in getresponse
    response.begin()
  File "/home2/kyrylo/.pyenv/versions/3.10.12/lib/python3.10/http/client.py", line 318, in begin
    version, status, reason = self._read_status()
  File "/home2/kyrylo/.pyenv/versions/3.10.12/lib/python3.10/http/client.py", line 279, in _read_status
    line = str(self.fp.readline(_MAXLINE + 1), "iso-8859-1")
  File "/home2/kyrylo/.pyenv/versions/3.10.12/lib/python3.10/socket.py", line 705, in readinto
    return self._sock.recv_into(b)
  File "/home2/kyrylo/.pyenv/versions/3.10.12/lib/python3.10/ssl.py", line 1274, in recv_into
    return self.read(nbytes, buffer)
  File "/home2/kyrylo/.pyenv/versions/3.10.12/lib/python3.10/ssl.py", line 1130, in read
    return self._sslobj.read(len, buffer)
TimeoutError: The read operation timed out

The above exception was the direct cause of the following exception:

Traceback (most recent call last):
  File "/home2/kyrylo/Minimal/lib/python3.10/site-packages/requests/adapters.py", line 486, in send
    resp = conn.urlopen(
  File "/home2/kyrylo/Minimal/lib/python3.10/site-packages/urllib3/connectionpool.py", line 847, in urlopen
    retries = retries.increment(
  File "/home2/kyrylo/Minimal/lib/python3.10/site-packages/urllib3/util/retry.py", line 470, in increment
    raise reraise(type(error), error, _stacktrace)
  File "/home2/kyrylo/Minimal/lib/python3.10/site-packages/urllib3/util/util.py", line 39, in reraise
    raise value
  File "/home2/kyrylo/Minimal/lib/python3.10/site-packages/urllib3/connectionpool.py", line 793, in urlopen
    response = self._make_request(
  File "/home2/kyrylo/Minimal/lib/python3.10/site-packages/urllib3/connectionpool.py", line 539, in _make_request
    self._raise_timeout(err=e, url=url, timeout_value=read_timeout)
  File "/home2/kyrylo/Minimal/lib/python3.10/site-packages/urllib3/connectionpool.py", line 370, in _raise_timeout
    raise ReadTimeoutError(
urllib3.exceptions.ReadTimeoutError: HTTPSConnectionPool(host='api.wandb.ai', port=443): Read timed out. (read timeout=20)

During handling of the above exception, another exception occurred:

Traceback (most recent call last):
  File "/home2/kyrylo/Minimal/lib/python3.10/site-packages/wandb/sdk/lib/retry.py", line 131, in __call__
    result = self._call_fn(*args, **kwargs)
  File "/home2/kyrylo/Minimal/lib/python3.10/site-packages/wandb/sdk/internal/internal_api.py", line 369, in execute
    return self.client.execute(*args, **kwargs)  # type: ignore
  File "/home2/kyrylo/Minimal/lib/python3.10/site-packages/wandb/vendor/gql-0.2.0/wandb_gql/client.py", line 52, in execute
    result = self._get_result(document, *args, **kwargs)
  File "/home2/kyrylo/Minimal/lib/python3.10/site-packages/wandb/vendor/gql-0.2.0/wandb_gql/client.py", line 60, in _get_result
    return self.transport.execute(document, *args, **kwargs)
  File "/home2/kyrylo/Minimal/lib/python3.10/site-packages/wandb/sdk/lib/gql_request.py", line 58, in execute
    request = self.session.post(self.url, **post_args)
  File "/home2/kyrylo/Minimal/lib/python3.10/site-packages/requests/sessions.py", line 637, in post
    return self.request("POST", url, data=data, json=json, **kwargs)
  File "/home2/kyrylo/Minimal/lib/python3.10/site-packages/requests/sessions.py", line 589, in request
    resp = self.send(prep, **send_kwargs)
  File "/home2/kyrylo/Minimal/lib/python3.10/site-packages/requests/sessions.py", line 703, in send
    r = adapter.send(request, **kwargs)
  File "/home2/kyrylo/Minimal/lib/python3.10/site-packages/requests/adapters.py", line 532, in send
    raise ReadTimeout(e, request=request)
requests.exceptions.ReadTimeout: HTTPSConnectionPool(host='api.wandb.ai', port=443): Read timed out. (read timeout=20)
2025-01-08 21:02:18,948 ERROR   MainThread:39936 [wandb_init.py:init():774] encountered error: Run initialization has timed out after 90.0 sec. 
Please refer to the documentation for additional information: https://docs.wandb.ai/guides/track/tracking-faq#initstarterror-error-communicating-with-wandb-process-
2025-01-08 21:02:19,122 ERROR   MainThread:39936 [wandb_init.py:init():1199] Run initialization has timed out after 90.0 sec. 
Please refer to the documentation for additional information: https://docs.wandb.ai/guides/track/tracking-faq#initstarterror-error-communicating-with-wandb-process-
Traceback (most recent call last):
  File "/home2/kyrylo/Minimal/lib/python3.10/site-packages/wandb/sdk/wandb_init.py", line 1181, in init
    run = wi.init()
  File "/home2/kyrylo/Minimal/lib/python3.10/site-packages/wandb/sdk/wandb_init.py", line 780, in init
    raise error
wandb.errors.CommError: Run initialization has timed out after 90.0 sec. 
Please refer to the documentation for additional information: https://docs.wandb.ai/guides/track/tracking-faq#initstarterror-error-communicating-with-wandb-process-
2025-01-08 21:02:20,129 WARNING MsgRouterThr:39936 [router.py:message_loop():77] message_loop has been closed
